[2025-05-03 21:25:36 +0000] [1] [INFO] Starting gunicorn 23.0.0
[2025-05-03 21:25:36 +0000] [1] [INFO] Listening at: http://0.0.0.0:5000 (1)
[2025-05-03 21:25:36 +0000] [1] [INFO] Using worker: sync
[2025-05-03 21:25:36 +0000] [9] [INFO] Booting worker with pid: 9
[2025-05-03 21:25:36 +0000] [10] [INFO] Booting worker with pid: 10
[2025-05-03 21:25:36 +0000] [11] [INFO] Booting worker with pid: 11
[2025-05-03 21:25:36 +0000] [12] [INFO] Booting worker with pid: 12
[2025-05-03 21:26:50 +0000] [1] [INFO] Handling signal: term
[2025-05-03 21:26:50 +0000] [12] [INFO] Worker exiting (pid: 12)
[2025-05-03 21:26:50 +0000] [9] [INFO] Worker exiting (pid: 9)
[2025-05-03 21:26:50 +0000] [11] [INFO] Worker exiting (pid: 11)
[2025-05-03 21:26:50 +0000] [10] [INFO] Worker exiting (pid: 10)
[2025-05-03 21:26:50 +0000] [1] [INFO] Shutting down: Master
[2025-05-03 21:27:26 +0000] [1] [INFO] Starting gunicorn 23.0.0
[2025-05-03 21:27:26 +0000] [1] [INFO] Listening at: http://0.0.0.0:5000 (1)
[2025-05-03 21:27:26 +0000] [1] [INFO] Using worker: sync
[2025-05-03 21:27:26 +0000] [9] [INFO] Booting worker with pid: 9
[2025-05-03 21:27:26 +0000] [10] [INFO] Booting worker with pid: 10
[2025-05-03 21:27:26 +0000] [11] [INFO] Booting worker with pid: 11
[2025-05-03 21:27:26 +0000] [12] [INFO] Booting worker with pid: 12
[2025-05-03 21:28:31 +0000] [1] [INFO] Handling signal: term
[2025-05-03 21:28:31 +0000] [9] [INFO] Worker exiting (pid: 9)
[2025-05-03 21:28:31 +0000] [10] [INFO] Worker exiting (pid: 10)
[2025-05-03 21:28:31 +0000] [11] [INFO] Worker exiting (pid: 11)
[2025-05-03 21:28:31 +0000] [12] [INFO] Worker exiting (pid: 12)
[2025-05-03 21:28:32 +0000] [1] [INFO] Shutting down: Master
[2025-05-03 21:28:54 +0000] [1] [INFO] Starting gunicorn 23.0.0
[2025-05-03 21:28:54 +0000] [1] [INFO] Listening at: http://0.0.0.0:5000 (1)
[2025-05-03 21:28:54 +0000] [1] [INFO] Using worker: sync
[2025-05-03 21:28:54 +0000] [9] [INFO] Booting worker with pid: 9
[2025-05-03 21:28:54 +0000] [10] [INFO] Booting worker with pid: 10
[2025-05-03 21:28:54 +0000] [11] [INFO] Booting worker with pid: 11
[2025-05-03 21:28:54 +0000] [12] [INFO] Booting worker with pid: 12
[2025-05-03 21:29:18,003] ERROR in app: Exception on / [GET]
Traceback (most recent call last):
  File "/usr/local/lib/python3.9/site-packages/flask/app.py", line 917, in full_dispatch_request
    rv = self.dispatch_request()
  File "/usr/local/lib/python3.9/site-packages/flask/app.py", line 891, in dispatch_request
    self.raise_routing_exception(req)
  File "/usr/local/lib/python3.9/site-packages/flask/app.py", line 500, in raise_routing_exception
    raise request.routing_exception  # type: ignore[misc]
  File "/usr/local/lib/python3.9/site-packages/flask/ctx.py", line 362, in match_request
    result = self.url_adapter.match(return_rule=True)  # type: ignore
  File "/usr/local/lib/python3.9/site-packages/werkzeug/routing/map.py", line 629, in match
    raise NotFound() from None
werkzeug.exceptions.NotFound: 404 Not Found: The requested URL was not found on the server. If you entered the URL manually please check your spelling and try again.

During handling of the above exception, another exception occurred:

Traceback (most recent call last):
  File "/usr/local/lib/python3.9/site-packages/flask/app.py", line 1511, in wsgi_app
    response = self.full_dispatch_request()
  File "/usr/local/lib/python3.9/site-packages/flask/app.py", line 919, in full_dispatch_request
    rv = self.handle_user_exception(e)
  File "/usr/local/lib/python3.9/site-packages/flask/app.py", line 802, in handle_user_exception
    return self.handle_http_exception(e)
  File "/usr/local/lib/python3.9/site-packages/flask/app.py", line 777, in handle_http_exception
    return self.ensure_sync(handler)(e)  # type: ignore[no-any-return]
  File "/app/app/__init__.py", line 55, in page_not_found
    return render_template('error.html', error="404 - Page Not Found"), 404
  File "/usr/local/lib/python3.9/site-packages/flask/templating.py", line 149, in render_template
    template = app.jinja_env.get_or_select_template(template_name_or_list)
  File "/usr/local/lib/python3.9/site-packages/jinja2/environment.py", line 1087, in get_or_select_template
    return self.get_template(template_name_or_list, parent, globals)
  File "/usr/local/lib/python3.9/site-packages/jinja2/environment.py", line 1016, in get_template
    return self._load_template(name, globals)
  File "/usr/local/lib/python3.9/site-packages/jinja2/environment.py", line 975, in _load_template
    template = self.loader.load(self, name, self.make_globals(globals))
  File "/usr/local/lib/python3.9/site-packages/jinja2/loaders.py", line 126, in load
    source, filename, uptodate = self.get_source(environment, name)
  File "/usr/local/lib/python3.9/site-packages/flask/templating.py", line 65, in get_source
    return self._get_source_fast(environment, template)
  File "/usr/local/lib/python3.9/site-packages/flask/templating.py", line 99, in _get_source_fast
    raise TemplateNotFound(template)
jinja2.exceptions.TemplateNotFound: error.html
[2025-05-03 21:29:18 +0000] [9] [ERROR] Socket error processing request.
Traceback (most recent call last):
  File "/usr/local/lib/python3.9/site-packages/flask/app.py", line 917, in full_dispatch_request
    rv = self.dispatch_request()
  File "/usr/local/lib/python3.9/site-packages/flask/app.py", line 891, in dispatch_request
    self.raise_routing_exception(req)
  File "/usr/local/lib/python3.9/site-packages/flask/app.py", line 500, in raise_routing_exception
    raise request.routing_exception  # type: ignore[misc]
  File "/usr/local/lib/python3.9/site-packages/flask/ctx.py", line 362, in match_request
    result = self.url_adapter.match(return_rule=True)  # type: ignore
  File "/usr/local/lib/python3.9/site-packages/werkzeug/routing/map.py", line 629, in match
    raise NotFound() from None
werkzeug.exceptions.NotFound: 404 Not Found: The requested URL was not found on the server. If you entered the URL manually please check your spelling and try again.

During handling of the above exception, another exception occurred:

Traceback (most recent call last):
  File "/usr/local/lib/python3.9/site-packages/flask/app.py", line 1511, in wsgi_app
    response = self.full_dispatch_request()
  File "/usr/local/lib/python3.9/site-packages/flask/app.py", line 919, in full_dispatch_request
    rv = self.handle_user_exception(e)
  File "/usr/local/lib/python3.9/site-packages/flask/app.py", line 802, in handle_user_exception
    return self.handle_http_exception(e)
  File "/usr/local/lib/python3.9/site-packages/flask/app.py", line 777, in handle_http_exception
    return self.ensure_sync(handler)(e)  # type: ignore[no-any-return]
  File "/app/app/__init__.py", line 55, in page_not_found
    return render_template('error.html', error="404 - Page Not Found"), 404
  File "/usr/local/lib/python3.9/site-packages/flask/templating.py", line 149, in render_template
    template = app.jinja_env.get_or_select_template(template_name_or_list)
  File "/usr/local/lib/python3.9/site-packages/jinja2/environment.py", line 1087, in get_or_select_template
    return self.get_template(template_name_or_list, parent, globals)
  File "/usr/local/lib/python3.9/site-packages/jinja2/environment.py", line 1016, in get_template
    return self._load_template(name, globals)
  File "/usr/local/lib/python3.9/site-packages/jinja2/environment.py", line 975, in _load_template
    template = self.loader.load(self, name, self.make_globals(globals))
  File "/usr/local/lib/python3.9/site-packages/jinja2/loaders.py", line 126, in load
    source, filename, uptodate = self.get_source(environment, name)
  File "/usr/local/lib/python3.9/site-packages/flask/templating.py", line 65, in get_source
    return self._get_source_fast(environment, template)
  File "/usr/local/lib/python3.9/site-packages/flask/templating.py", line 99, in _get_source_fast
    raise TemplateNotFound(template)
jinja2.exceptions.TemplateNotFound: error.html

During handling of the above exception, another exception occurred:

Traceback (most recent call last):
  File "/usr/local/lib/python3.9/site-packages/gunicorn/workers/sync.py", line 134, in handle
    self.handle_request(listener, req, client, addr)
  File "/usr/local/lib/python3.9/site-packages/gunicorn/workers/sync.py", line 192, in handle_request
    util.reraise(*sys.exc_info())
  File "/usr/local/lib/python3.9/site-packages/gunicorn/util.py", line 640, in reraise
    raise value
  File "/usr/local/lib/python3.9/site-packages/gunicorn/workers/sync.py", line 177, in handle_request
    respiter = self.wsgi(environ, resp.start_response)
  File "/usr/local/lib/python3.9/site-packages/flask/app.py", line 1536, in __call__
    return self.wsgi_app(environ, start_response)
  File "/usr/local/lib/python3.9/site-packages/flask/app.py", line 1514, in wsgi_app
    response = self.handle_exception(e)
  File "/usr/local/lib/python3.9/site-packages/flask/app.py", line 860, in handle_exception
    server_error = self.ensure_sync(handler)(server_error)
  File "/app/app/__init__.py", line 59, in server_error
    return render_template('error.html', error="500 - Internal Server Error"), 500
  File "/usr/local/lib/python3.9/site-packages/flask/templating.py", line 149, in render_template
    template = app.jinja_env.get_or_select_template(template_name_or_list)
  File "/usr/local/lib/python3.9/site-packages/jinja2/environment.py", line 1087, in get_or_select_template
    return self.get_template(template_name_or_list, parent, globals)
  File "/usr/local/lib/python3.9/site-packages/jinja2/environment.py", line 1016, in get_template
    return self._load_template(name, globals)
  File "/usr/local/lib/python3.9/site-packages/jinja2/environment.py", line 975, in _load_template
    template = self.loader.load(self, name, self.make_globals(globals))
  File "/usr/local/lib/python3.9/site-packages/jinja2/loaders.py", line 126, in load
    source, filename, uptodate = self.get_source(environment, name)
  File "/usr/local/lib/python3.9/site-packages/flask/templating.py", line 65, in get_source
    return self._get_source_fast(environment, template)
  File "/usr/local/lib/python3.9/site-packages/flask/templating.py", line 99, in _get_source_fast
    raise TemplateNotFound(template)
jinja2.exceptions.TemplateNotFound: error.html
[2025-05-03 21:29:18,996] ERROR in app: Exception on / [GET]
Traceback (most recent call last):
  File "/usr/local/lib/python3.9/site-packages/flask/app.py", line 917, in full_dispatch_request
    rv = self.dispatch_request()
  File "/usr/local/lib/python3.9/site-packages/flask/app.py", line 891, in dispatch_request
    self.raise_routing_exception(req)
  File "/usr/local/lib/python3.9/site-packages/flask/app.py", line 500, in raise_routing_exception
    raise request.routing_exception  # type: ignore[misc]
  File "/usr/local/lib/python3.9/site-packages/flask/ctx.py", line 362, in match_request
    result = self.url_adapter.match(return_rule=True)  # type: ignore
  File "/usr/local/lib/python3.9/site-packages/werkzeug/routing/map.py", line 629, in match
    raise NotFound() from None
werkzeug.exceptions.NotFound: 404 Not Found: The requested URL was not found on the server. If you entered the URL manually please check your spelling and try again.

During handling of the above exception, another exception occurred:

Traceback (most recent call last):
  File "/usr/local/lib/python3.9/site-packages/flask/app.py", line 1511, in wsgi_app
    response = self.full_dispatch_request()
  File "/usr/local/lib/python3.9/site-packages/flask/app.py", line 919, in full_dispatch_request
    rv = self.handle_user_exception(e)
  File "/usr/local/lib/python3.9/site-packages/flask/app.py", line 802, in handle_user_exception
    return self.handle_http_exception(e)
  File "/usr/local/lib/python3.9/site-packages/flask/app.py", line 777, in handle_http_exception
    return self.ensure_sync(handler)(e)  # type: ignore[no-any-return]
  File "/app/app/__init__.py", line 55, in page_not_found
    return render_template('error.html', error="404 - Page Not Found"), 404
  File "/usr/local/lib/python3.9/site-packages/flask/templating.py", line 149, in render_template
    template = app.jinja_env.get_or_select_template(template_name_or_list)
  File "/usr/local/lib/python3.9/site-packages/jinja2/environment.py", line 1087, in get_or_select_template
    return self.get_template(template_name_or_list, parent, globals)
  File "/usr/local/lib/python3.9/site-packages/jinja2/environment.py", line 1016, in get_template
    return self._load_template(name, globals)
  File "/usr/local/lib/python3.9/site-packages/jinja2/environment.py", line 975, in _load_template
    template = self.loader.load(self, name, self.make_globals(globals))
  File "/usr/local/lib/python3.9/site-packages/jinja2/loaders.py", line 126, in load
    source, filename, uptodate = self.get_source(environment, name)
  File "/usr/local/lib/python3.9/site-packages/flask/templating.py", line 65, in get_source
    return self._get_source_fast(environment, template)
  File "/usr/local/lib/python3.9/site-packages/flask/templating.py", line 99, in _get_source_fast
    raise TemplateNotFound(template)
jinja2.exceptions.TemplateNotFound: error.html
[2025-05-03 21:29:18 +0000] [12] [ERROR] Socket error processing request.
Traceback (most recent call last):
  File "/usr/local/lib/python3.9/site-packages/flask/app.py", line 917, in full_dispatch_request
    rv = self.dispatch_request()
  File "/usr/local/lib/python3.9/site-packages/flask/app.py", line 891, in dispatch_request
    self.raise_routing_exception(req)
  File "/usr/local/lib/python3.9/site-packages/flask/app.py", line 500, in raise_routing_exception
    raise request.routing_exception  # type: ignore[misc]
  File "/usr/local/lib/python3.9/site-packages/flask/ctx.py", line 362, in match_request
    result = self.url_adapter.match(return_rule=True)  # type: ignore
  File "/usr/local/lib/python3.9/site-packages/werkzeug/routing/map.py", line 629, in match
    raise NotFound() from None
werkzeug.exceptions.NotFound: 404 Not Found: The requested URL was not found on the server. If you entered the URL manually please check your spelling and try again.

During handling of the above exception, another exception occurred:

Traceback (most recent call last):
  File "/usr/local/lib/python3.9/site-packages/flask/app.py", line 1511, in wsgi_app
    response = self.full_dispatch_request()
  File "/usr/local/lib/python3.9/site-packages/flask/app.py", line 919, in full_dispatch_request
    rv = self.handle_user_exception(e)
  File "/usr/local/lib/python3.9/site-packages/flask/app.py", line 802, in handle_user_exception
    return self.handle_http_exception(e)
  File "/usr/local/lib/python3.9/site-packages/flask/app.py", line 777, in handle_http_exception
    return self.ensure_sync(handler)(e)  # type: ignore[no-any-return]
  File "/app/app/__init__.py", line 55, in page_not_found
    return render_template('error.html', error="404 - Page Not Found"), 404
  File "/usr/local/lib/python3.9/site-packages/flask/templating.py", line 149, in render_template
    template = app.jinja_env.get_or_select_template(template_name_or_list)
  File "/usr/local/lib/python3.9/site-packages/jinja2/environment.py", line 1087, in get_or_select_template
    return self.get_template(template_name_or_list, parent, globals)
  File "/usr/local/lib/python3.9/site-packages/jinja2/environment.py", line 1016, in get_template
    return self._load_template(name, globals)
  File "/usr/local/lib/python3.9/site-packages/jinja2/environment.py", line 975, in _load_template
    template = self.loader.load(self, name, self.make_globals(globals))
  File "/usr/local/lib/python3.9/site-packages/jinja2/loaders.py", line 126, in load
    source, filename, uptodate = self.get_source(environment, name)
  File "/usr/local/lib/python3.9/site-packages/flask/templating.py", line 65, in get_source
    return self._get_source_fast(environment, template)
  File "/usr/local/lib/python3.9/site-packages/flask/templating.py", line 99, in _get_source_fast
    raise TemplateNotFound(template)
jinja2.exceptions.TemplateNotFound: error.html

During handling of the above exception, another exception occurred:

Traceback (most recent call last):
  File "/usr/local/lib/python3.9/site-packages/gunicorn/workers/sync.py", line 134, in handle
    self.handle_request(listener, req, client, addr)
  File "/usr/local/lib/python3.9/site-packages/gunicorn/workers/sync.py", line 192, in handle_request
    util.reraise(*sys.exc_info())
  File "/usr/local/lib/python3.9/site-packages/gunicorn/util.py", line 640, in reraise
    raise value
  File "/usr/local/lib/python3.9/site-packages/gunicorn/workers/sync.py", line 177, in handle_request
    respiter = self.wsgi(environ, resp.start_response)
  File "/usr/local/lib/python3.9/site-packages/flask/app.py", line 1536, in __call__
    return self.wsgi_app(environ, start_response)
  File "/usr/local/lib/python3.9/site-packages/flask/app.py", line 1514, in wsgi_app
    response = self.handle_exception(e)
  File "/usr/local/lib/python3.9/site-packages/flask/app.py", line 860, in handle_exception
    server_error = self.ensure_sync(handler)(server_error)
  File "/app/app/__init__.py", line 59, in server_error
    return render_template('error.html', error="500 - Internal Server Error"), 500
  File "/usr/local/lib/python3.9/site-packages/flask/templating.py", line 149, in render_template
    template = app.jinja_env.get_or_select_template(template_name_or_list)
  File "/usr/local/lib/python3.9/site-packages/jinja2/environment.py", line 1087, in get_or_select_template
    return self.get_template(template_name_or_list, parent, globals)
  File "/usr/local/lib/python3.9/site-packages/jinja2/environment.py", line 1016, in get_template
    return self._load_template(name, globals)
  File "/usr/local/lib/python3.9/site-packages/jinja2/environment.py", line 975, in _load_template
    template = self.loader.load(self, name, self.make_globals(globals))
  File "/usr/local/lib/python3.9/site-packages/jinja2/loaders.py", line 126, in load
    source, filename, uptodate = self.get_source(environment, name)
  File "/usr/local/lib/python3.9/site-packages/flask/templating.py", line 65, in get_source
    return self._get_source_fast(environment, template)
  File "/usr/local/lib/python3.9/site-packages/flask/templating.py", line 99, in _get_source_fast
    raise TemplateNotFound(template)
jinja2.exceptions.TemplateNotFound: error.html
[2025-05-03 21:29:19,002] ERROR in app: Exception on / [GET]
Traceback (most recent call last):
  File "/usr/local/lib/python3.9/site-packages/flask/app.py", line 917, in full_dispatch_request
    rv = self.dispatch_request()
  File "/usr/local/lib/python3.9/site-packages/flask/app.py", line 891, in dispatch_request
    self.raise_routing_exception(req)
  File "/usr/local/lib/python3.9/site-packages/flask/app.py", line 500, in raise_routing_exception
    raise request.routing_exception  # type: ignore[misc]
  File "/usr/local/lib/python3.9/site-packages/flask/ctx.py", line 362, in match_request
    result = self.url_adapter.match(return_rule=True)  # type: ignore
  File "/usr/local/lib/python3.9/site-packages/werkzeug/routing/map.py", line 629, in match
    raise NotFound() from None
werkzeug.exceptions.NotFound: 404 Not Found: The requested URL was not found on the server. If you entered the URL manually please check your spelling and try again.

During handling of the above exception, another exception occurred:

Traceback (most recent call last):
  File "/usr/local/lib/python3.9/site-packages/flask/app.py", line 1511, in wsgi_app
    response = self.full_dispatch_request()
  File "/usr/local/lib/python3.9/site-packages/flask/app.py", line 919, in full_dispatch_request
    rv = self.handle_user_exception(e)
  File "/usr/local/lib/python3.9/site-packages/flask/app.py", line 802, in handle_user_exception
    return self.handle_http_exception(e)
  File "/usr/local/lib/python3.9/site-packages/flask/app.py", line 777, in handle_http_exception
    return self.ensure_sync(handler)(e)  # type: ignore[no-any-return]
  File "/app/app/__init__.py", line 55, in page_not_found
    return render_template('error.html', error="404 - Page Not Found"), 404
  File "/usr/local/lib/python3.9/site-packages/flask/templating.py", line 149, in render_template
    template = app.jinja_env.get_or_select_template(template_name_or_list)
  File "/usr/local/lib/python3.9/site-packages/jinja2/environment.py", line 1087, in get_or_select_template
    return self.get_template(template_name_or_list, parent, globals)
  File "/usr/local/lib/python3.9/site-packages/jinja2/environment.py", line 1016, in get_template
    return self._load_template(name, globals)
  File "/usr/local/lib/python3.9/site-packages/jinja2/environment.py", line 975, in _load_template
    template = self.loader.load(self, name, self.make_globals(globals))
  File "/usr/local/lib/python3.9/site-packages/jinja2/loaders.py", line 126, in load
    source, filename, uptodate = self.get_source(environment, name)
  File "/usr/local/lib/python3.9/site-packages/flask/templating.py", line 65, in get_source
    return self._get_source_fast(environment, template)
  File "/usr/local/lib/python3.9/site-packages/flask/templating.py", line 99, in _get_source_fast
    raise TemplateNotFound(template)
jinja2.exceptions.TemplateNotFound: error.html
[2025-05-03 21:29:19 +0000] [11] [ERROR] Socket error processing request.
Traceback (most recent call last):
  File "/usr/local/lib/python3.9/site-packages/flask/app.py", line 917, in full_dispatch_request
    rv = self.dispatch_request()
  File "/usr/local/lib/python3.9/site-packages/flask/app.py", line 891, in dispatch_request
    self.raise_routing_exception(req)
  File "/usr/local/lib/python3.9/site-packages/flask/app.py", line 500, in raise_routing_exception
    raise request.routing_exception  # type: ignore[misc]
  File "/usr/local/lib/python3.9/site-packages/flask/ctx.py", line 362, in match_request
    result = self.url_adapter.match(return_rule=True)  # type: ignore
  File "/usr/local/lib/python3.9/site-packages/werkzeug/routing/map.py", line 629, in match
    raise NotFound() from None
werkzeug.exceptions.NotFound: 404 Not Found: The requested URL was not found on the server. If you entered the URL manually please check your spelling and try again.

During handling of the above exception, another exception occurred:

Traceback (most recent call last):
  File "/usr/local/lib/python3.9/site-packages/flask/app.py", line 1511, in wsgi_app
    response = self.full_dispatch_request()
  File "/usr/local/lib/python3.9/site-packages/flask/app.py", line 919, in full_dispatch_request
    rv = self.handle_user_exception(e)
  File "/usr/local/lib/python3.9/site-packages/flask/app.py", line 802, in handle_user_exception
    return self.handle_http_exception(e)
  File "/usr/local/lib/python3.9/site-packages/flask/app.py", line 777, in handle_http_exception
    return self.ensure_sync(handler)(e)  # type: ignore[no-any-return]
  File "/app/app/__init__.py", line 55, in page_not_found
    return render_template('error.html', error="404 - Page Not Found"), 404
  File "/usr/local/lib/python3.9/site-packages/flask/templating.py", line 149, in render_template
    template = app.jinja_env.get_or_select_template(template_name_or_list)
  File "/usr/local/lib/python3.9/site-packages/jinja2/environment.py", line 1087, in get_or_select_template
    return self.get_template(template_name_or_list, parent, globals)
  File "/usr/local/lib/python3.9/site-packages/jinja2/environment.py", line 1016, in get_template
    return self._load_template(name, globals)
  File "/usr/local/lib/python3.9/site-packages/jinja2/environment.py", line 975, in _load_template
    template = self.loader.load(self, name, self.make_globals(globals))
  File "/usr/local/lib/python3.9/site-packages/jinja2/loaders.py", line 126, in load
    source, filename, uptodate = self.get_source(environment, name)
  File "/usr/local/lib/python3.9/site-packages/flask/templating.py", line 65, in get_source
    return self._get_source_fast(environment, template)
  File "/usr/local/lib/python3.9/site-packages/flask/templating.py", line 99, in _get_source_fast
    raise TemplateNotFound(template)
jinja2.exceptions.TemplateNotFound: error.html

During handling of the above exception, another exception occurred:

Traceback (most recent call last):
  File "/usr/local/lib/python3.9/site-packages/gunicorn/workers/sync.py", line 134, in handle
    self.handle_request(listener, req, client, addr)
  File "/usr/local/lib/python3.9/site-packages/gunicorn/workers/sync.py", line 192, in handle_request
    util.reraise(*sys.exc_info())
  File "/usr/local/lib/python3.9/site-packages/gunicorn/util.py", line 640, in reraise
    raise value
  File "/usr/local/lib/python3.9/site-packages/gunicorn/workers/sync.py", line 177, in handle_request
    respiter = self.wsgi(environ, resp.start_response)
  File "/usr/local/lib/python3.9/site-packages/flask/app.py", line 1536, in __call__
    return self.wsgi_app(environ, start_response)
  File "/usr/local/lib/python3.9/site-packages/flask/app.py", line 1514, in wsgi_app
    response = self.handle_exception(e)
  File "/usr/local/lib/python3.9/site-packages/flask/app.py", line 860, in handle_exception
    server_error = self.ensure_sync(handler)(server_error)
  File "/app/app/__init__.py", line 59, in server_error
    return render_template('error.html', error="500 - Internal Server Error"), 500
  File "/usr/local/lib/python3.9/site-packages/flask/templating.py", line 149, in render_template
    template = app.jinja_env.get_or_select_template(template_name_or_list)
  File "/usr/local/lib/python3.9/site-packages/jinja2/environment.py", line 1087, in get_or_select_template
    return self.get_template(template_name_or_list, parent, globals)
  File "/usr/local/lib/python3.9/site-packages/jinja2/environment.py", line 1016, in get_template
    return self._load_template(name, globals)
  File "/usr/local/lib/python3.9/site-packages/jinja2/environment.py", line 975, in _load_template
    template = self.loader.load(self, name, self.make_globals(globals))
  File "/usr/local/lib/python3.9/site-packages/jinja2/loaders.py", line 126, in load
    source, filename, uptodate = self.get_source(environment, name)
  File "/usr/local/lib/python3.9/site-packages/flask/templating.py", line 65, in get_source
    return self._get_source_fast(environment, template)
  File "/usr/local/lib/python3.9/site-packages/flask/templating.py", line 99, in _get_source_fast
    raise TemplateNotFound(template)
jinja2.exceptions.TemplateNotFound: error.html
[2025-05-03 21:29:19,007] ERROR in app: Exception on / [GET]
Traceback (most recent call last):
  File "/usr/local/lib/python3.9/site-packages/flask/app.py", line 917, in full_dispatch_request
    rv = self.dispatch_request()
  File "/usr/local/lib/python3.9/site-packages/flask/app.py", line 891, in dispatch_request
    self.raise_routing_exception(req)
  File "/usr/local/lib/python3.9/site-packages/flask/app.py", line 500, in raise_routing_exception
    raise request.routing_exception  # type: ignore[misc]
  File "/usr/local/lib/python3.9/site-packages/flask/ctx.py", line 362, in match_request
    result = self.url_adapter.match(return_rule=True)  # type: ignore
  File "/usr/local/lib/python3.9/site-packages/werkzeug/routing/map.py", line 629, in match
    raise NotFound() from None
werkzeug.exceptions.NotFound: 404 Not Found: The requested URL was not found on the server. If you entered the URL manually please check your spelling and try again.

During handling of the above exception, another exception occurred:

Traceback (most recent call last):
  File "/usr/local/lib/python3.9/site-packages/flask/app.py", line 1511, in wsgi_app
    response = self.full_dispatch_request()
  File "/usr/local/lib/python3.9/site-packages/flask/app.py", line 919, in full_dispatch_request
    rv = self.handle_user_exception(e)
  File "/usr/local/lib/python3.9/site-packages/flask/app.py", line 802, in handle_user_exception
    return self.handle_http_exception(e)
  File "/usr/local/lib/python3.9/site-packages/flask/app.py", line 777, in handle_http_exception
    return self.ensure_sync(handler)(e)  # type: ignore[no-any-return]
  File "/app/app/__init__.py", line 55, in page_not_found
    return render_template('error.html', error="404 - Page Not Found"), 404
  File "/usr/local/lib/python3.9/site-packages/flask/templating.py", line 149, in render_template
    template = app.jinja_env.get_or_select_template(template_name_or_list)
  File "/usr/local/lib/python3.9/site-packages/jinja2/environment.py", line 1087, in get_or_select_template
    return self.get_template(template_name_or_list, parent, globals)
  File "/usr/local/lib/python3.9/site-packages/jinja2/environment.py", line 1016, in get_template
    return self._load_template(name, globals)
  File "/usr/local/lib/python3.9/site-packages/jinja2/environment.py", line 975, in _load_template
    template = self.loader.load(self, name, self.make_globals(globals))
  File "/usr/local/lib/python3.9/site-packages/jinja2/loaders.py", line 126, in load
    source, filename, uptodate = self.get_source(environment, name)
  File "/usr/local/lib/python3.9/site-packages/flask/templating.py", line 65, in get_source
    return self._get_source_fast(environment, template)
  File "/usr/local/lib/python3.9/site-packages/flask/templating.py", line 99, in _get_source_fast
    raise TemplateNotFound(template)
jinja2.exceptions.TemplateNotFound: error.html
[2025-05-03 21:29:19 +0000] [11] [ERROR] Socket error processing request.
Traceback (most recent call last):
  File "/usr/local/lib/python3.9/site-packages/flask/app.py", line 917, in full_dispatch_request
    rv = self.dispatch_request()
  File "/usr/local/lib/python3.9/site-packages/flask/app.py", line 891, in dispatch_request
    self.raise_routing_exception(req)
  File "/usr/local/lib/python3.9/site-packages/flask/app.py", line 500, in raise_routing_exception
    raise request.routing_exception  # type: ignore[misc]
  File "/usr/local/lib/python3.9/site-packages/flask/ctx.py", line 362, in match_request
    result = self.url_adapter.match(return_rule=True)  # type: ignore
  File "/usr/local/lib/python3.9/site-packages/werkzeug/routing/map.py", line 629, in match
    raise NotFound() from None
werkzeug.exceptions.NotFound: 404 Not Found: The requested URL was not found on the server. If you entered the URL manually please check your spelling and try again.

During handling of the above exception, another exception occurred:

Traceback (most recent call last):
  File "/usr/local/lib/python3.9/site-packages/flask/app.py", line 1511, in wsgi_app
    response = self.full_dispatch_request()
  File "/usr/local/lib/python3.9/site-packages/flask/app.py", line 919, in full_dispatch_request
    rv = self.handle_user_exception(e)
  File "/usr/local/lib/python3.9/site-packages/flask/app.py", line 802, in handle_user_exception
    return self.handle_http_exception(e)
  File "/usr/local/lib/python3.9/site-packages/flask/app.py", line 777, in handle_http_exception
    return self.ensure_sync(handler)(e)  # type: ignore[no-any-return]
  File "/app/app/__init__.py", line 55, in page_not_found
    return render_template('error.html', error="404 - Page Not Found"), 404
  File "/usr/local/lib/python3.9/site-packages/flask/templating.py", line 149, in render_template
    template = app.jinja_env.get_or_select_template(template_name_or_list)
  File "/usr/local/lib/python3.9/site-packages/jinja2/environment.py", line 1087, in get_or_select_template
    return self.get_template(template_name_or_list, parent, globals)
  File "/usr/local/lib/python3.9/site-packages/jinja2/environment.py", line 1016, in get_template
    return self._load_template(name, globals)
  File "/usr/local/lib/python3.9/site-packages/jinja2/environment.py", line 975, in _load_template
    template = self.loader.load(self, name, self.make_globals(globals))
  File "/usr/local/lib/python3.9/site-packages/jinja2/loaders.py", line 126, in load
    source, filename, uptodate = self.get_source(environment, name)
  File "/usr/local/lib/python3.9/site-packages/flask/templating.py", line 65, in get_source
    return self._get_source_fast(environment, template)
  File "/usr/local/lib/python3.9/site-packages/flask/templating.py", line 99, in _get_source_fast
    raise TemplateNotFound(template)
jinja2.exceptions.TemplateNotFound: error.html

During handling of the above exception, another exception occurred:

Traceback (most recent call last):
  File "/usr/local/lib/python3.9/site-packages/gunicorn/workers/sync.py", line 134, in handle
    self.handle_request(listener, req, client, addr)
  File "/usr/local/lib/python3.9/site-packages/gunicorn/workers/sync.py", line 192, in handle_request
    util.reraise(*sys.exc_info())
  File "/usr/local/lib/python3.9/site-packages/gunicorn/util.py", line 640, in reraise
    raise value
  File "/usr/local/lib/python3.9/site-packages/gunicorn/workers/sync.py", line 177, in handle_request
    respiter = self.wsgi(environ, resp.start_response)
  File "/usr/local/lib/python3.9/site-packages/flask/app.py", line 1536, in __call__
    return self.wsgi_app(environ, start_response)
  File "/usr/local/lib/python3.9/site-packages/flask/app.py", line 1514, in wsgi_app
    response = self.handle_exception(e)
  File "/usr/local/lib/python3.9/site-packages/flask/app.py", line 860, in handle_exception
    server_error = self.ensure_sync(handler)(server_error)
  File "/app/app/__init__.py", line 59, in server_error
    return render_template('error.html', error="500 - Internal Server Error"), 500
  File "/usr/local/lib/python3.9/site-packages/flask/templating.py", line 149, in render_template
    template = app.jinja_env.get_or_select_template(template_name_or_list)
  File "/usr/local/lib/python3.9/site-packages/jinja2/environment.py", line 1087, in get_or_select_template
    return self.get_template(template_name_or_list, parent, globals)
  File "/usr/local/lib/python3.9/site-packages/jinja2/environment.py", line 1016, in get_template
    return self._load_template(name, globals)
  File "/usr/local/lib/python3.9/site-packages/jinja2/environment.py", line 975, in _load_template
    template = self.loader.load(self, name, self.make_globals(globals))
  File "/usr/local/lib/python3.9/site-packages/jinja2/loaders.py", line 126, in load
    source, filename, uptodate = self.get_source(environment, name)
  File "/usr/local/lib/python3.9/site-packages/flask/templating.py", line 65, in get_source
    return self._get_source_fast(environment, template)
  File "/usr/local/lib/python3.9/site-packages/flask/templating.py", line 99, in _get_source_fast
    raise TemplateNotFound(template)
jinja2.exceptions.TemplateNotFound: error.html
[2025-05-03 21:29:51,306] ERROR in app: Exception on /api [HEAD]
Traceback (most recent call last):
  File "/usr/local/lib/python3.9/site-packages/flask/app.py", line 917, in full_dispatch_request
    rv = self.dispatch_request()
  File "/usr/local/lib/python3.9/site-packages/flask/app.py", line 891, in dispatch_request
    self.raise_routing_exception(req)
  File "/usr/local/lib/python3.9/site-packages/flask/app.py", line 500, in raise_routing_exception
    raise request.routing_exception  # type: ignore[misc]
  File "/usr/local/lib/python3.9/site-packages/flask/ctx.py", line 362, in match_request
    result = self.url_adapter.match(return_rule=True)  # type: ignore
  File "/usr/local/lib/python3.9/site-packages/werkzeug/routing/map.py", line 629, in match
    raise NotFound() from None
werkzeug.exceptions.NotFound: 404 Not Found: The requested URL was not found on the server. If you entered the URL manually please check your spelling and try again.

During handling of the above exception, another exception occurred:

Traceback (most recent call last):
  File "/usr/local/lib/python3.9/site-packages/flask/app.py", line 1511, in wsgi_app
    response = self.full_dispatch_request()
  File "/usr/local/lib/python3.9/site-packages/flask/app.py", line 919, in full_dispatch_request
    rv = self.handle_user_exception(e)
  File "/usr/local/lib/python3.9/site-packages/flask/app.py", line 802, in handle_user_exception
    return self.handle_http_exception(e)
  File "/usr/local/lib/python3.9/site-packages/flask/app.py", line 777, in handle_http_exception
    return self.ensure_sync(handler)(e)  # type: ignore[no-any-return]
  File "/app/app/__init__.py", line 55, in page_not_found
    return render_template('error.html', error="404 - Page Not Found"), 404
  File "/usr/local/lib/python3.9/site-packages/flask/templating.py", line 149, in render_template
    template = app.jinja_env.get_or_select_template(template_name_or_list)
  File "/usr/local/lib/python3.9/site-packages/jinja2/environment.py", line 1087, in get_or_select_template
    return self.get_template(template_name_or_list, parent, globals)
  File "/usr/local/lib/python3.9/site-packages/jinja2/environment.py", line 1016, in get_template
    return self._load_template(name, globals)
  File "/usr/local/lib/python3.9/site-packages/jinja2/environment.py", line 975, in _load_template
    template = self.loader.load(self, name, self.make_globals(globals))
  File "/usr/local/lib/python3.9/site-packages/jinja2/loaders.py", line 126, in load
    source, filename, uptodate = self.get_source(environment, name)
  File "/usr/local/lib/python3.9/site-packages/flask/templating.py", line 65, in get_source
    return self._get_source_fast(environment, template)
  File "/usr/local/lib/python3.9/site-packages/flask/templating.py", line 99, in _get_source_fast
    raise TemplateNotFound(template)
jinja2.exceptions.TemplateNotFound: error.html
[2025-05-03 21:29:51 +0000] [12] [ERROR] Socket error processing request.
Traceback (most recent call last):
  File "/usr/local/lib/python3.9/site-packages/flask/app.py", line 917, in full_dispatch_request
    rv = self.dispatch_request()
  File "/usr/local/lib/python3.9/site-packages/flask/app.py", line 891, in dispatch_request
    self.raise_routing_exception(req)
  File "/usr/local/lib/python3.9/site-packages/flask/app.py", line 500, in raise_routing_exception
    raise request.routing_exception  # type: ignore[misc]
  File "/usr/local/lib/python3.9/site-packages/flask/ctx.py", line 362, in match_request
    result = self.url_adapter.match(return_rule=True)  # type: ignore
  File "/usr/local/lib/python3.9/site-packages/werkzeug/routing/map.py", line 629, in match
    raise NotFound() from None
werkzeug.exceptions.NotFound: 404 Not Found: The requested URL was not found on the server. If you entered the URL manually please check your spelling and try again.

During handling of the above exception, another exception occurred:

Traceback (most recent call last):
  File "/usr/local/lib/python3.9/site-packages/flask/app.py", line 1511, in wsgi_app
    response = self.full_dispatch_request()
  File "/usr/local/lib/python3.9/site-packages/flask/app.py", line 919, in full_dispatch_request
    rv = self.handle_user_exception(e)
  File "/usr/local/lib/python3.9/site-packages/flask/app.py", line 802, in handle_user_exception
    return self.handle_http_exception(e)
  File "/usr/local/lib/python3.9/site-packages/flask/app.py", line 777, in handle_http_exception
    return self.ensure_sync(handler)(e)  # type: ignore[no-any-return]
  File "/app/app/__init__.py", line 55, in page_not_found
    return render_template('error.html', error="404 - Page Not Found"), 404
  File "/usr/local/lib/python3.9/site-packages/flask/templating.py", line 149, in render_template
    template = app.jinja_env.get_or_select_template(template_name_or_list)
  File "/usr/local/lib/python3.9/site-packages/jinja2/environment.py", line 1087, in get_or_select_template
    return self.get_template(template_name_or_list, parent, globals)
  File "/usr/local/lib/python3.9/site-packages/jinja2/environment.py", line 1016, in get_template
    return self._load_template(name, globals)
  File "/usr/local/lib/python3.9/site-packages/jinja2/environment.py", line 975, in _load_template
    template = self.loader.load(self, name, self.make_globals(globals))
  File "/usr/local/lib/python3.9/site-packages/jinja2/loaders.py", line 126, in load
    source, filename, uptodate = self.get_source(environment, name)
  File "/usr/local/lib/python3.9/site-packages/flask/templating.py", line 65, in get_source
    return self._get_source_fast(environment, template)
  File "/usr/local/lib/python3.9/site-packages/flask/templating.py", line 99, in _get_source_fast
    raise TemplateNotFound(template)
jinja2.exceptions.TemplateNotFound: error.html

During handling of the above exception, another exception occurred:

Traceback (most recent call last):
  File "/usr/local/lib/python3.9/site-packages/gunicorn/workers/sync.py", line 134, in handle
    self.handle_request(listener, req, client, addr)
  File "/usr/local/lib/python3.9/site-packages/gunicorn/workers/sync.py", line 192, in handle_request
    util.reraise(*sys.exc_info())
  File "/usr/local/lib/python3.9/site-packages/gunicorn/util.py", line 640, in reraise
    raise value
  File "/usr/local/lib/python3.9/site-packages/gunicorn/workers/sync.py", line 177, in handle_request
    respiter = self.wsgi(environ, resp.start_response)
  File "/usr/local/lib/python3.9/site-packages/flask/app.py", line 1536, in __call__
    return self.wsgi_app(environ, start_response)
  File "/usr/local/lib/python3.9/site-packages/flask/app.py", line 1514, in wsgi_app
    response = self.handle_exception(e)
  File "/usr/local/lib/python3.9/site-packages/flask/app.py", line 860, in handle_exception
    server_error = self.ensure_sync(handler)(server_error)
  File "/app/app/__init__.py", line 59, in server_error
    return render_template('error.html', error="500 - Internal Server Error"), 500
  File "/usr/local/lib/python3.9/site-packages/flask/templating.py", line 149, in render_template
    template = app.jinja_env.get_or_select_template(template_name_or_list)
  File "/usr/local/lib/python3.9/site-packages/jinja2/environment.py", line 1087, in get_or_select_template
    return self.get_template(template_name_or_list, parent, globals)
  File "/usr/local/lib/python3.9/site-packages/jinja2/environment.py", line 1016, in get_template
    return self._load_template(name, globals)
  File "/usr/local/lib/python3.9/site-packages/jinja2/environment.py", line 975, in _load_template
    template = self.loader.load(self, name, self.make_globals(globals))
  File "/usr/local/lib/python3.9/site-packages/jinja2/loaders.py", line 126, in load
    source, filename, uptodate = self.get_source(environment, name)
  File "/usr/local/lib/python3.9/site-packages/flask/templating.py", line 65, in get_source
    return self._get_source_fast(environment, template)
  File "/usr/local/lib/python3.9/site-packages/flask/templating.py", line 99, in _get_source_fast
    raise TemplateNotFound(template)
jinja2.exceptions.TemplateNotFound: error.html
[2025-05-03 21:31:32 +0000] [1] [INFO] Handling signal: term
[2025-05-03 21:31:32 +0000] [9] [INFO] Worker exiting (pid: 9)
[2025-05-03 21:31:32 +0000] [11] [INFO] Worker exiting (pid: 11)
[2025-05-03 21:31:32 +0000] [10] [INFO] Worker exiting (pid: 10)
[2025-05-03 21:31:32 +0000] [12] [INFO] Worker exiting (pid: 12)
[2025-05-03 21:31:32 +0000] [1] [INFO] Shutting down: Master
[2025-05-03 21:36:58 +0000] [1] [INFO] Starting gunicorn 23.0.0
[2025-05-03 21:36:58 +0000] [1] [INFO] Listening at: http://0.0.0.0:5000 (1)
[2025-05-03 21:36:58 +0000] [1] [INFO] Using worker: sync
[2025-05-03 21:36:58 +0000] [9] [INFO] Booting worker with pid: 9
[2025-05-03 21:36:58 +0000] [10] [INFO] Booting worker with pid: 10
[2025-05-03 21:36:58 +0000] [11] [INFO] Booting worker with pid: 11
[2025-05-03 21:36:58 +0000] [12] [INFO] Booting worker with pid: 12
[2025-05-03 21:37:02,287] ERROR in __init__: Database health check failed: Textual SQL expression 'SELECT 1' should be explicitly declared as text('SELECT 1')
[2025-05-03 21:37:32 +0000] [1] [INFO] Handling signal: term
[2025-05-03 21:37:32 +0000] [9] [INFO] Worker exiting (pid: 9)
[2025-05-03 21:37:32 +0000] [11] [INFO] Worker exiting (pid: 11)
[2025-05-03 21:37:32 +0000] [12] [INFO] Worker exiting (pid: 12)
[2025-05-03 21:37:32 +0000] [10] [INFO] Worker exiting (pid: 10)
[2025-05-03 21:37:32 +0000] [1] [INFO] Shutting down: Master
[2025-05-03 21:37:40 +0000] [1] [INFO] Starting gunicorn 23.0.0
[2025-05-03 21:37:40 +0000] [1] [INFO] Listening at: http://0.0.0.0:5000 (1)
[2025-05-03 21:37:40 +0000] [1] [INFO] Using worker: sync
[2025-05-03 21:37:40 +0000] [9] [INFO] Booting worker with pid: 9
[2025-05-03 21:37:40 +0000] [10] [INFO] Booting worker with pid: 10
[2025-05-03 21:37:40 +0000] [11] [INFO] Booting worker with pid: 11
[2025-05-03 21:37:40 +0000] [12] [INFO] Booting worker with pid: 12
[2025-05-03 21:37:44,199] ERROR in __init__: Database health check failed: Textual SQL expression 'SELECT 1' should be explicitly declared as text('SELECT 1')
[2025-05-03 21:38:12 +0000] [1] [INFO] Handling signal: term
[2025-05-03 21:38:12 +0000] [11] [INFO] Worker exiting (pid: 11)
[2025-05-03 21:38:12 +0000] [9] [INFO] Worker exiting (pid: 9)
[2025-05-03 21:38:12 +0000] [12] [INFO] Worker exiting (pid: 12)
[2025-05-03 21:38:12 +0000] [10] [INFO] Worker exiting (pid: 10)
[2025-05-03 21:38:12 +0000] [1] [INFO] Shutting down: Master
[2025-05-03 21:38:13 +0000] [1] [INFO] Starting gunicorn 23.0.0
[2025-05-03 21:38:13 +0000] [1] [INFO] Listening at: http://0.0.0.0:5000 (1)
[2025-05-03 21:38:13 +0000] [1] [INFO] Using worker: sync
[2025-05-03 21:38:13 +0000] [9] [INFO] Booting worker with pid: 9
[2025-05-03 21:38:13 +0000] [10] [INFO] Booting worker with pid: 10
[2025-05-03 21:38:13 +0000] [11] [INFO] Booting worker with pid: 11
[2025-05-03 21:38:13 +0000] [12] [INFO] Booting worker with pid: 12
[2025-05-03 21:38:16,056] ERROR in __init__: Database health check failed: Textual SQL expression 'SELECT 1' should be explicitly declared as text('SELECT 1')
[2025-05-03 21:41:15 +0000] [1] [INFO] Handling signal: term
[2025-05-03 21:41:15 +0000] [10] [INFO] Worker exiting (pid: 10)
[2025-05-03 21:41:15 +0000] [9] [INFO] Worker exiting (pid: 9)
[2025-05-03 21:41:15 +0000] [11] [INFO] Worker exiting (pid: 11)
[2025-05-03 21:41:15 +0000] [12] [INFO] Worker exiting (pid: 12)
[2025-05-03 21:41:15 +0000] [1] [INFO] Shutting down: Master
[2025-05-03 21:41:24 +0000] [1] [INFO] Starting gunicorn 23.0.0
[2025-05-03 21:41:24 +0000] [1] [INFO] Listening at: http://0.0.0.0:5000 (1)
[2025-05-03 21:41:24 +0000] [1] [INFO] Using worker: sync
[2025-05-03 21:41:24 +0000] [10] [INFO] Booting worker with pid: 10
[2025-05-03 21:41:24 +0000] [11] [INFO] Booting worker with pid: 11
[2025-05-03 21:41:24 +0000] [12] [INFO] Booting worker with pid: 12
[2025-05-03 21:41:24 +0000] [13] [INFO] Booting worker with pid: 13
[2025-05-03 21:41:27,828] ERROR in __init__: Database health check failed: Textual SQL expression 'SELECT 1' should be explicitly declared as text('SELECT 1')
[2025-05-03 21:43:09 +0000] [1] [INFO] Handling signal: term
[2025-05-03 21:43:09 +0000] [12] [INFO] Worker exiting (pid: 12)
[2025-05-03 21:43:09 +0000] [10] [INFO] Worker exiting (pid: 10)
[2025-05-03 21:43:09 +0000] [11] [INFO] Worker exiting (pid: 11)
[2025-05-03 21:43:09 +0000] [13] [INFO] Worker exiting (pid: 13)
[2025-05-03 21:43:09 +0000] [1] [INFO] Shutting down: Master
[2025-05-03 21:43:10 +0000] [1] [INFO] Starting gunicorn 23.0.0
[2025-05-03 21:43:10 +0000] [1] [INFO] Listening at: http://0.0.0.0:5000 (1)
[2025-05-03 21:43:10 +0000] [1] [INFO] Using worker: sync
[2025-05-03 21:43:10 +0000] [9] [INFO] Booting worker with pid: 9
[2025-05-03 21:43:10 +0000] [10] [INFO] Booting worker with pid: 10
[2025-05-03 21:43:10 +0000] [11] [INFO] Booting worker with pid: 11
[2025-05-03 21:43:10 +0000] [12] [INFO] Booting worker with pid: 12
[2025-05-03 21:43:13,702] ERROR in __init__: Database health check failed: Textual SQL expression 'SELECT 1' should be explicitly declared as text('SELECT 1')
[2025-05-03 21:43:25 +0000] [1] [INFO] Handling signal: term
[2025-05-03 21:43:25 +0000] [10] [INFO] Worker exiting (pid: 10)
[2025-05-03 21:43:25 +0000] [9] [INFO] Worker exiting (pid: 9)
[2025-05-03 21:43:25 +0000] [11] [INFO] Worker exiting (pid: 11)
[2025-05-03 21:43:25 +0000] [12] [INFO] Worker exiting (pid: 12)
[2025-05-03 21:43:25 +0000] [1] [INFO] Shutting down: Master
[2025-05-03 21:43:28 +0000] [1] [INFO] Starting gunicorn 23.0.0
[2025-05-03 21:43:28 +0000] [1] [INFO] Listening at: http://0.0.0.0:5000 (1)
[2025-05-03 21:43:28 +0000] [1] [INFO] Using worker: sync
[2025-05-03 21:43:28 +0000] [9] [INFO] Booting worker with pid: 9
[2025-05-03 21:43:28 +0000] [10] [INFO] Booting worker with pid: 10
[2025-05-03 21:43:28 +0000] [11] [INFO] Booting worker with pid: 11
[2025-05-03 21:43:28 +0000] [12] [INFO] Booting worker with pid: 12
[2025-05-03 21:45:51,610] ERROR in __init__: Unhandled exception: blog/index.html
[2025-05-03 21:46:39 +0000] [1] [INFO] Handling signal: term
[2025-05-03 21:46:39 +0000] [11] [INFO] Worker exiting (pid: 11)
[2025-05-03 21:46:39 +0000] [9] [INFO] Worker exiting (pid: 9)
[2025-05-03 21:46:39 +0000] [10] [INFO] Worker exiting (pid: 10)
[2025-05-03 21:46:39 +0000] [12] [INFO] Worker exiting (pid: 12)
[2025-05-03 21:46:40 +0000] [1] [INFO] Shutting down: Master
[2025-05-03 21:46:53 +0000] [1] [INFO] Starting gunicorn 23.0.0
[2025-05-03 21:46:53 +0000] [1] [INFO] Listening at: http://0.0.0.0:5000 (1)
[2025-05-03 21:46:53 +0000] [1] [INFO] Using worker: sync
[2025-05-03 21:46:53 +0000] [9] [INFO] Booting worker with pid: 9
[2025-05-03 21:46:53 +0000] [10] [INFO] Booting worker with pid: 10
[2025-05-03 21:46:53 +0000] [11] [INFO] Booting worker with pid: 11
[2025-05-03 21:46:53 +0000] [12] [INFO] Booting worker with pid: 12
[2025-05-03 21:47:12,437] ERROR in __init__: Unhandled exception: (psycopg2.errors.UndefinedColumn) column blog_posts.updated_at does not exist
LINE 1: ..., blog_posts.created_at AS blog_posts_created_at, blog_posts...
                                                             ^
HINT:  Perhaps you meant to reference the column "blog_posts.created_at".

[SQL: SELECT blog_posts.id AS blog_posts_id, blog_posts.title AS blog_posts_title, blog_posts.content AS blog_posts_content, blog_posts.topic AS blog_posts_topic, blog_posts.keywords AS blog_posts_keywords, blog_posts.published AS blog_posts_published, blog_posts.created_at AS blog_posts_created_at, blog_posts.updated_at AS blog_posts_updated_at, blog_posts.published_at AS blog_posts_published_at, blog_posts.generation_metadata AS blog_posts_generation_metadata, blog_posts.status AS blog_posts_status, blog_posts.current_version AS blog_posts_current_version, blog_posts.has_outline AS blog_posts_has_outline, blog_posts.outline_json AS blog_posts_outline_json, blog_posts.target_audience AS blog_posts_target_audience, blog_posts.content_purpose AS blog_posts_content_purpose, blog_posts.quality_score AS blog_posts_quality_score, blog_posts.last_autosave AS blog_posts_last_autosave 
FROM blog_posts]
(Background on this error at: https://sqlalche.me/e/20/f405)
[2025-05-03 21:48:25,864] ERROR in __init__: Unhandled exception: (psycopg2.errors.UndefinedColumn) column blog_posts.updated_at does not exist
LINE 1: ..., blog_posts.created_at AS blog_posts_created_at, blog_posts...
                                                             ^
HINT:  Perhaps you meant to reference the column "blog_posts.created_at".

[SQL: SELECT blog_posts.id AS blog_posts_id, blog_posts.title AS blog_posts_title, blog_posts.content AS blog_posts_content, blog_posts.topic AS blog_posts_topic, blog_posts.keywords AS blog_posts_keywords, blog_posts.published AS blog_posts_published, blog_posts.created_at AS blog_posts_created_at, blog_posts.updated_at AS blog_posts_updated_at, blog_posts.published_at AS blog_posts_published_at, blog_posts.generation_metadata AS blog_posts_generation_metadata, blog_posts.status AS blog_posts_status, blog_posts.current_version AS blog_posts_current_version, blog_posts.has_outline AS blog_posts_has_outline, blog_posts.outline_json AS blog_posts_outline_json, blog_posts.target_audience AS blog_posts_target_audience, blog_posts.content_purpose AS blog_posts_content_purpose, blog_posts.quality_score AS blog_posts_quality_score, blog_posts.last_autosave AS blog_posts_last_autosave 
FROM blog_posts]
(Background on this error at: https://sqlalche.me/e/20/f405)
[2025-05-03 21:48:31 +0000] [1] [INFO] Handling signal: term
[2025-05-03 21:48:31 +0000] [12] [INFO] Worker exiting (pid: 12)
[2025-05-03 21:48:31 +0000] [9] [INFO] Worker exiting (pid: 9)
[2025-05-03 21:48:31 +0000] [11] [INFO] Worker exiting (pid: 11)
[2025-05-03 21:48:31 +0000] [10] [INFO] Worker exiting (pid: 10)
[2025-05-03 21:48:31 +0000] [1] [INFO] Shutting down: Master
[2025-05-03 21:48:40 +0000] [1] [INFO] Starting gunicorn 23.0.0
[2025-05-03 21:48:40 +0000] [1] [INFO] Listening at: http://0.0.0.0:5000 (1)
[2025-05-03 21:48:40 +0000] [1] [INFO] Using worker: sync
[2025-05-03 21:48:40 +0000] [9] [INFO] Booting worker with pid: 9
[2025-05-03 21:48:40 +0000] [10] [INFO] Booting worker with pid: 10
[2025-05-03 21:48:40 +0000] [11] [INFO] Booting worker with pid: 11
[2025-05-03 21:48:40 +0000] [12] [INFO] Booting worker with pid: 12
[2025-05-03 22:23:29 +0000] [1] [INFO] Handling signal: term
[2025-05-03 22:23:29 +0000] [9] [INFO] Worker exiting (pid: 9)
[2025-05-03 22:23:29 +0000] [11] [INFO] Worker exiting (pid: 11)
[2025-05-03 22:23:29 +0000] [10] [INFO] Worker exiting (pid: 10)
[2025-05-03 22:23:29 +0000] [12] [INFO] Worker exiting (pid: 12)
[2025-05-03 22:23:29 +0000] [1] [INFO] Shutting down: Master
[2025-05-03 22:52:54 +0000] [1] [INFO] Starting gunicorn 23.0.0
[2025-05-03 22:52:54 +0000] [1] [INFO] Listening at: http://0.0.0.0:5000 (1)
[2025-05-03 22:52:54 +0000] [1] [INFO] Using worker: sync
[2025-05-03 22:52:54 +0000] [8] [INFO] Booting worker with pid: 8
[2025-05-03 22:52:54 +0000] [9] [INFO] Booting worker with pid: 9
[2025-05-03 22:52:54 +0000] [10] [INFO] Booting worker with pid: 10
[2025-05-03 22:52:54 +0000] [11] [INFO] Booting worker with pid: 11
[2025-05-03 22:55:37 +0000] [1] [INFO] Handling signal: term
[2025-05-03 22:55:37 +0000] [9] [INFO] Worker exiting (pid: 9)
[2025-05-03 22:55:37 +0000] [11] [INFO] Worker exiting (pid: 11)
[2025-05-03 22:55:37 +0000] [10] [INFO] Worker exiting (pid: 10)
